<mujoco model="mg400-solidworks_asm">

  <option iterations="50" timestep="0.001" solver="PGS" gravity="0 0 -9.81" />

  <compiler angle="radian" meshdir="meshes" eulerseq="zyx" autolimits="true" />

  <default>

    <joint limited="true" />

    <geom condim="4" contype="1" conaffinity="15" friction="0.9 0.2 0.2" solref="0.001 2" />
    <motor ctrllimited="true" />
    <equality solref="0.001 2" />
    <default class="visualgeom">
      <geom material="visualgeom" condim="1" contype="0" conaffinity="0" />
    </default>
  </default>

  <asset>
    <mesh name="base_link" file="base_link.stl" />
    <mesh name="MG400_Link_1" file="MG400_Link_1.stl" />
    <mesh name="MG400_Link_3" file="MG400_Link_3.stl" />
    <mesh name="MG400_Link_6" file="MG400_Link_6.stl" />
    <mesh name="MG400_Link_10" file="MG400_Link_10.stl" />
    <mesh name="MG400_Link_12" file="MG400_Link_12.stl" />
    <mesh name="MG400_Link_6p" file="MG400_Link_6p.stl" />
    <mesh name="MG400_Link_9" file="MG400_Link_9.stl" />
    <mesh name="MG400_Link_2" file="MG400_Link_2.stl" />
    <mesh name="MG400_Link_5" file="MG400_Link_5.stl" />
    <mesh name="MG400_Link_4" file="MG400_Link_4.stl" />

    <mesh name="MG400_Gripper" file="MG400_Gripper.stl"/>

    <texture name="texplane" type="2d" builtin="checker" mark="edge" markrgb="0.35 0.38 0.42"
             rgb1="0.19 0.21 0.24" rgb2="0.24 0.26 0.29" width="512" height="512" />
    <material name="matplane" texture="texplane" texrepeat="6 6" texuniform="true"
              reflectance="0.15" shininess="0.4" specular="0.3" />
    <material name="visualgeom" rgba="0.5 0.9 0.2 1" />
  </asset>

  <worldbody>
    <light directional="true" diffuse="0.4 0.4 0.4" specular="0.1 0.1 0.1" pos="0 0 5.0" dir="0 0 -1" castshadow="false" />
    <light directional="true" diffuse="0.6 0.6 0.6" specular="0.2 0.2 0.2" pos="0 0 4" dir="0 0 -1" />
    <geom name="floor" size="2 2 0.01" type="plane" material="matplane"/>

    <body name="root" pos="0.4 0 0." quat="1 0 0 0">
      <site name="imu" size="0.01" pos="0 0 0" />
      <geom type="mesh" rgba="1 1 1 1" mesh="base_link" contype="1" conaffinity="0" density="0" group="1" class="visualgeom" />
      <geom type="mesh" rgba="1 1 1 1" mesh="base_link" />
      <body name="MG400_Link_1" pos="0.005 0 0.1125">
        <inertial pos="0.0046223 6.741e-05 0.067494" quat="0.388265 0.652383 -0.345683 0.551498" mass="1.7705" diaginertia="0.00744552 0.00610906 0.00570802" />
        <joint name="MG400_Joint_1" pos="0 0 0" axis="0 0 -1" range="-3.14 3.14"/>
        <geom type="mesh" rgba="1 1 1 1" mesh="MG400_Link_1" contype="1" conaffinity="0" density="0" group="1" class="visualgeom" />
        <geom type="mesh" rgba="1 1 1 1" mesh="MG400_Link_1" />
        <body name="MG400_Link_3" pos="-0.0435 0.019275 0.1155" quat="-2.59734e-06 2.59735e-06 -0.707108 0.707105">
          <inertial pos="-0.0028592 -0.059627 0.018793" quat="0.708808 0.705252 -0.00967681 -0.0108753" mass="0.086612" diaginertia="0.000338924 0.000307797 3.86186e-05" />
          <joint name="MG400_Joint_3" pos="0 0 0" axis="0 0 -1" range="-3.14 3.14"/>
          <geom type="mesh" rgba="1 1 1 1" mesh="MG400_Link_3" contype="1" conaffinity="0" density="0" group="1" class="visualgeom" />
          <geom type="mesh" rgba="1 1 1 1" mesh="MG400_Link_3" />
          <body name="MG400_Link_6" pos="0 -0.175 0.002">
            <inertial pos="0.082092 0.0048639 0.017388" quat="0.45937 0.534932 0.463681 0.536494" mass="0.037521" diaginertia="0.000164359 0.000164228 2.52139e-06" />
            <joint name="MG400_Joint_6" pos="0 0 0" axis="0 0 -1" range="-3.14 3.14"/>
            <geom type="mesh" rgba="1 1 1 1" mesh="MG400_Link_6" contype="1" conaffinity="0" density="0" group="1" class="visualgeom" />
            <geom type="mesh" rgba="1 1 1 1" mesh="MG400_Link_6" />

            <body name="MG400_Link_10" pos="0.175 0 0.0065686" quat="0 0 0 1">
              <inertial pos="-0.0387878 -0.00264953 0.0107465" quat="0.582376 0.373304 -0.608542 0.388792" mass="0.0628979" diaginertia="5.42418e-05 5.16813e-05 2.97735e-05" />
              <joint name="MG400_Joint_10" pos="0 0 0" axis="0 0 -1" range="-3.14 3.14"/>
              <geom type="mesh" rgba="1 1 1 1" mesh="MG400_Link_10" contype="1" conaffinity="0" density="0" group="1" class="visualgeom" />
              <geom type="mesh" rgba="1 1 1 1" mesh="MG400_Link_10" />

              <body name="MG400_Link_12" pos="-0.066 -0.039181 0.010024" quat="0.70710678 -0.70710678 0 0">
                <inertial pos="4.183e-07 0 0.035031" quat="0.924006 -2.28296e-06 5.51672e-06 -0.382377" mass="0.096528" diaginertia="4.9859e-05 4.9859e-05 2.1305e-05" />
                <geom type="mesh" rgba="1 1 1 1" mesh="MG400_Link_12" contype="1" conaffinity="0" density="0" group="1" class="visualgeom" />
                <geom type="mesh" rgba="1 1 1 1" mesh="MG400_Link_12" />
                <body name="MG400_Gripper" pos="0.0 -0.0 -0.059" quat="0.1 -0.0 -0.0 0.0">
                  <inertial pos="4.0931e-07 2.3808e-08 0.0" quat="0.500003 0.500003 -0.499997 0.499997" mass="0.025073" diaginertia="3.0059e-06 2.7676e-06 2.7676e-06"/>
                  <joint name="MG400_Joint_Gripper" pos="0 0 0" axis="1.1921e-05 0 1" range="-3.14 3.14"/>
                  <geom type="mesh" rgba="0.79216 0.81961 0.93333 1" mesh="MG400_Gripper" contype="1" conaffinity="0" density="0" group="1" class="visualgeom"/>
                  <geom type="mesh" rgba="0.79216 0.81961 0.93333 1" mesh="MG400_Gripper"/>
                  <site name="gripper_magnet_site" pos="0 0 0.0" size="0.005" type="sphere" rgba="1 0 0 0.5"/>
                </body>
              </body>
            </body>
          </body>
          <body name="MG400_Link_6p" pos="0 -0.175 0.0092749">
            <inertial pos="-0.0051145 -0.027022 0.010021" quat="0.0607234 0.70451 -0.0607603 0.704476" mass="0.036669" diaginertia="2.3497e-05 1.69769e-05 6.94621e-06" />
            <joint name="MG400_Joint_6p" pos="0 0 0" axis="0 0 -1" range="-3.14 3.14"/>
            <geom type="mesh" rgba="1 1 1 1" mesh="MG400_Link_6p" contype="1" conaffinity="0" density="0" group="1" class="visualgeom" />
            <geom type="mesh" rgba="1 1 1 1" mesh="MG400_Link_6p" />
            <body name="MG400_Link_9" pos="0.028925 -0.034472 -0.00625">
              <inertial pos="0.087778 -0.006685 0.01625" quat="0.494881 0.494888 0.505078 0.50505" mass="0.045357" diaginertia="0.00014181 0.00013205 2.00025e-05" />
              <joint name="MG400_Joint_9" pos="0 0 0" axis="0 0 -1" range="-3.14 3.14"/>
              <geom type="mesh" rgba="1 1 1 1" mesh="MG400_Link_9" contype="1" conaffinity="0" density="0" group="1" class="visualgeom" />
              <geom type="mesh" rgba="1 1 1 1" mesh="MG400_Link_9" />
            </body>
          </body>
        </body>
        <body name="MG400_Link_2" pos="-0.0435 -0.0037251 0.1155" quat="-2.59734e-06 2.59735e-06 -0.707108 0.707105">
          <inertial pos="-0.017283 1.7115e-06 -0.003756" quat="0 0.729341 0 0.68415" mass="0.0044786" diaginertia="1.70099e-06 1.6191e-06 1.33906e-07" />
          <joint name="MG400_Joint_2" pos="0 0 0" axis="0 0 -1" range="-1.0 0.5"/>
          <geom type="mesh" rgba="1 1 1 1" mesh="MG400_Link_2" contype="1" conaffinity="0" density="0" group="1" class="visualgeom" />
          <geom type="mesh" rgba="1 1 1 1" mesh="MG400_Link_2" />
          <body name="MG400_Link_5" pos="-0.043 0 -0.0057251">
            <inertial pos="0.0020358 -0.089342 -0.0025263" quat="0.499042 0.498242 -0.501587 0.501121" mass="0.0092247" diaginertia="3.5875e-05 3.57811e-05 1.38909e-07" />
            <joint name="MG400_Joint_5" pos="0 0 0" axis="0 0 -1" range="-3.14 3.14"/>
            <geom type="mesh" rgba="1 1 1 1" mesh="MG400_Link_5" contype="1" conaffinity="0" density="0" group="1" class="visualgeom" />
            <geom type="mesh" rgba="1 1 1 1" mesh="MG400_Link_5" />
          </body>
        </body>

        <body name="MG400_Link_4" pos="-0.0045289 0.020738 0.138" quat="0.5 0.5 -0.5 0.5">
          <inertial pos="0.073752 -0.020205 0.020216" quat="0.495341 0.508486 0.491467 0.504519" mass="0.066255" diaginertia="0.000219004 0.000200507 3.73968e-05" />
          <joint name="MG400_Joint_4" pos="0 0 0" axis="0 0 -1" range="-3.14 3.14"/>
          <geom type="mesh" rgba="1 1 1 1" mesh="MG400_Link_4" contype="1" conaffinity="0" density="0" group="1" class="visualgeom" />
          <geom type="mesh" rgba="1 1 1 1" mesh="MG400_Link_4" />
        </body>
      </body>
    </body>

    <body name="box" pos="0.15 0.09 0.03">
        <geom type="box" size="0.02 0.02 0.02" rgba="1 0 0 1" mass="0.1" contype="2" conaffinity="2" friction="0 0 0"/>
        <joint name="box_joint" type="free" damping="0.1" />
        <site name="box_site" type="box" size="0.02 0.02 0.02" rgba="1 0 0 1" />
    </body>

  </worldbody>

  <actuator>
    <motor name="MG400_Joint_1" joint="MG400_Joint_1"
           ctrllimited="true" ctrlrange="-100 100"
           forcelimited="true" forcerange="-100 100"/>

    <motor name="MG400_Joint_2" joint="MG400_Joint_2"
           ctrllimited="true" ctrlrange="-200 200"
           forcelimited="true" forcerange="-200 200"/>

    <motor name="MG400_Joint_3" joint="MG400_Joint_3"
           ctrllimited="true" ctrlrange="-200 200"
           forcelimited="true" forcerange="-200 200"/>

    <motor name="M0G400_Joint_Gripper" joint="MG400_Joint_Gripper"
           ctrllimited="true" ctrlrange="-100 100"
           forcelimited="true" forcerange="-100 100"/>
    <velocity name="box_vel" joint="box_joint" gear="1 0 0 0 0 0" ctrlrange="-1 1" />

  </actuator>

  <equality>

    <connect body1="MG400_Link_5" body2="MG400_Link_6" anchor="0 -0.175 0.002"/>
    <connect body1="MG400_Link_4" body2="MG400_Link_6p" anchor="0.175 0 0.0092749"/>
    <connect body1="MG400_Link_9" body2="MG400_Link_10" anchor="0.175 0 0.0065686"/>
    <weld name="gripper_weld" body1="MG400_Gripper" body2="box" active="false"/>
  </equality>

  <contact>
      <exclude body1="root" body2="MG400_Link_1"/>

      <exclude body1="MG400_Link_1" body2="MG400_Link_10"/>
      <exclude body1="MG400_Link_1" body2="MG400_Link_2"/>
      <exclude body1="MG400_Link_1" body2="MG400_Link_3"/>
      <exclude body1="MG400_Link_1" body2="MG400_Link_4"/>
      <exclude body1="MG400_Link_1" body2="MG400_Link_5"/>
      <exclude body1="MG400_Link_1" body2="MG400_Link_6"/>
      <exclude body1="MG400_Link_1" body2="MG400_Link_6p"/>
      <exclude body1="MG400_Link_1" body2="MG400_Link_9"/>

      <exclude body1="MG400_Link_10" body2="MG400_Link_2"/>
      <exclude body1="MG400_Link_10" body2="MG400_Link_3"/>
      <exclude body1="MG400_Link_10" body2="MG400_Link_4"/>
      <exclude body1="MG400_Link_10" body2="MG400_Link_5"/>
      <exclude body1="MG400_Link_10" body2="MG400_Link_6"/>
      <exclude body1="MG400_Link_10" body2="MG400_Link_6p"/>
      <exclude body1="MG400_Link_10" body2="MG400_Link_9"/>

      <exclude body1="MG400_Link_12" body2="MG400_Link_2"/>
      <exclude body1="MG400_Link_12" body2="MG400_Link_3"/>
      <exclude body1="MG400_Link_12" body2="MG400_Link_4"/>
      <exclude body1="MG400_Link_12" body2="MG400_Link_5"/>
      <exclude body1="MG400_Link_12" body2="MG400_Link_6"/>
      <exclude body1="MG400_Link_12" body2="MG400_Link_6p"/>
      <exclude body1="MG400_Link_12" body2="MG400_Link_9"/>

      <exclude body1="MG400_Link_2" body2="MG400_Link_3"/>
      <exclude body1="MG400_Link_2" body2="MG400_Link_4"/>
      <exclude body1="MG400_Link_2" body2="MG400_Link_5"/>
      <exclude body1="MG400_Link_2" body2="MG400_Link_6"/>
      <exclude body1="MG400_Link_2" body2="MG400_Link_6p"/>
      <exclude body1="MG400_Link_2" body2="MG400_Link_9"/>

      <exclude body1="MG400_Link_3" body2="MG400_Link_4"/>
      <exclude body1="MG400_Link_3" body2="MG400_Link_5"/>
      <exclude body1="MG400_Link_3" body2="MG400_Link_6"/>
      <exclude body1="MG400_Link_3" body2="MG400_Link_6p"/>
      <exclude body1="MG400_Link_3" body2="MG400_Link_9"/>

      <exclude body1="MG400_Link_4" body2="MG400_Link_5"/>
      <exclude body1="MG400_Link_4" body2="MG400_Link_6"/>
      <exclude body1="MG400_Link_4" body2="MG400_Link_6p"/>
      <exclude body1="MG400_Link_4" body2="MG400_Link_9"/>

      <exclude body1="MG400_Link_5" body2="MG400_Link_6"/>
      <exclude body1="MG400_Link_5" body2="MG400_Link_6p"/>
      <exclude body1="MG400_Link_5" body2="MG400_Link_9"/>

      <exclude body1="MG400_Link_6" body2="MG400_Link_6p"/>
      <exclude body1="MG400_Link_6" body2="MG400_Link_9"/>

      <exclude body1="MG400_Link_6p" body2="MG400_Link_9"/>

      <exclude body1="MG400_Gripper" body2="MG400_Link_6"/>
      <exclude body1="MG400_Gripper" body2="MG400_Link_6p"/>
      <exclude body1="MG400_Gripper" body2="MG400_Link_9"/>
      <exclude body1="MG400_Gripper" body2="MG400_Link_10"/>

    </contact>

</mujoco>